Workbook

Sheet social_security_prep
A1: year | B1: year_th | C1: article_33 | D1: article_39 | E1: article_40 | F1: total
A2: 2024 | B2: 2567 | C2: 12081112 | D2: 1719840 | E2: 11011863 | F2: 24812815
A3: 2023 | B3: 2566 | C3: 11890917 | D3: 1797848 | E3: 10958136 | F3: 24646901
A4: 2022 | B4: 2565 | C4: 11638041 | D4: 1879744 | E4: 10881050 | F4: 24398835
A5: 2021 | B5: 2564 | C5: 11137211 | D5: 1938895 | E5: 10664848 | F5: 23740954
A6: 2020 | B6: 2563 | C6: 11124209 | D6: 1799786 | E6: 3508970 | F6: 16432965
A7: 2019 | B7: 2562 | C7: 11686393 | D7: 1648118 | E7: 3242579 | F7: 16577090
A8: 2018 | B8: 2561 | C8: 11599338 | D8: 1561293 | E8: 2833960 | F8: 15994591

Sheet age_social_security_prep
A1: year_th | B1: year | C1: No_group_Age | D1: Age (years) | E1: Male | F1: Female | G1: Total
A2: 2567 | B2: 2024 | C2: 1_15-17 | D2: 15-17 | E2: 1662 | F2: 1217 | G2: 2879
A3: 2567 | B3: 2024 | C3: 2_18-19 | D3: 18-19 | E3: 26482 | F3: 21461 | G3: 47943
A4: 2567 | B4: 2024 | C4: 3_20-24 | D4: 20-24 | E4: 523562 | F4: 522514 | G4: 1046076
A5: 2567 | B5: 2024 | C5: 4_25-29 | D5: 25-29 | E5: 997425 | F5: 1114258 | G5: 2111683
A6: 2567 | B6: 2024 | C6: 5_30-34 | D6: 30-34 | E6: 1006925 | F6: 1078844 | G6: 2085769
A7: 2567 | B7: 2024 | C7: 6_35-39 | D7: 35-39 | E7: 865261 | F7: 902558 | G7: 1767819
A8: 2567 | B8: 2024 | C8: 7_40-44 | D8: 40-44 | E8: 827915 | F8: 846962 | G8: 1674877
A9: 2567 | B9: 2024 | C9: 8_45-49 | D9: 45-49 | E9: 723810 | F9: 702207 | G9: 1426017
A10: 2567 | B10: 2024 | C10: 9_50-54 | D10: 50-54 | E10: 538356 | F10: 499170 | G10: 1037526
A11: 2567 | B11: 2024 | C11: 10_55-59 | D11: 55-59 | E11: 334016 | F11: 289696 | G11: 623712
A12: 2567 | B12: 2024 | C12: 11_morethanequal60 | D12: >=60 | E12: 142892 | F12: 113919 | G12: 256811
A13: 2566 | B13: 2023 | C13: 1_15-17 | D13: 15-17 | E13: 2059 | F13: 1497 | G13: 3556
... A56: 2563 | B56: 2020 | C56: 11_morethanequal60 | D56: >=60 | E56: 80250 | F56: 58863 | G56: 139113

Sheet region_social_security_prep
A1: year | B1: year_th | C1: region | D1: article33
A2: 2024 | B2: 2567 | C2: กรุงเทพมหานครและปริมณฑล | D2: 6581014
A3: 2023 | B3: 2566 | C3: กรุงเทพมหานครและปริมณฑล | D3: 6500042
A4: 2022 | B4: 2565 | C4: กรุงเทพมหานครและปริมณฑล | D4: 6321761
A5: 2021 | B5: 2564 | C5: กรุงเทพมหานครและปริมณฑล | D5: 6008643
A6: 2020 | B6: 2563 | C6: กรุงเทพมหานครและปริมณฑล | D6: 6071306
A7: 2019 | B7: 2562 | C7: กรุงเทพมหานครและปริมณฑล | D7: 6390355
A8: 2018 | B8: 2561 | C8: กรุงเทพมหานครและปริมณฑล | D8: 6269976
A9: 2024 | B9: 2567 | C9: ภาคกลาง | D9: 620443
A10: 2023 | B10: 2566 | C10: ภาคกลาง | D10: 615870
A11: 2022 | B11: 2565 | C11: ภาคกลาง | D11: 627160
A12: 2021 | B12: 2564 | C12: ภาคกลาง | D12: 633523
A13: 2020 | B13: 2563 | C13: ภาคกลาง | D13: 627753
... A50: 2018 | B50: 2561 | C50: ภาคใต้ | D50: 847223

Sheet tax_collect_prep
A1: year | B1: year_th | C1: prov | D1: tax_type | E1: form_code | F1: amt_rcv | G1: region1 | H1: region
A2: =B2-543 -> 2025 | B2: 2568 | C2: เชียงราย | D2: 70 | E2: ทป3 | F2: 1838821.7 | G2: =VLOOKUP(C2,region!$B$1:$C$78,2,FALSE) -> ภาคเหนือ | H2: ภาคเหนือ
A3: =B3-543 -> 2025 | B3: 2568 | C3: เชียงราย | D3: 70 | E3: ภม60 | F3: 2583596.1 | G3: =VLOOKUP(C3,region!$B$1:$C$78,2,FALSE) -> ภาคเหนือ | H3: ภาคเหนือ
A4: =B4-543 -> 2025 | B4: 2568 | C4: เชียงใหม่ | D4: 1 | E4: ทป3 | F4: 2.4939505e+08 | G4: =VLOOKUP(C4,region!$B$1:$C$78,2,FALSE) -> ภาคเหนือ | H4: ภาคเหนือ
A5: =B5-543 -> 2025 | B5: 2568 | C5: เชียงใหม่ | D5: 1 | E5: ป2 | F5: 6154900 | G5: =VLOOKUP(C5,region!$B$1:$C$78,2,FALSE) -> ภาคเหนือ | H5: ภาคเหนือ
A6: =B6-543 -> 2025 | B6: 2568 | C6: เชียงใหม่ | D6: 1 | E6: ภงด1 | F6: 1.1642285e+09 | G6: =VLOOKUP(C6,region!$B$1:$C$78,2,FALSE) -> ภาคเหนือ | H6: ภาคเหนือ
A7: =B7-543 -> 2025 | B7: 2568 | C7: เชียงใหม่ | D7: 1 | E7: ภงด2 | F7: 3.6119372e+08 | G7: =VLOOKUP(C7,region!$B$1:$C$78,2,FALSE) -> ภาคเหนือ | H7: ภาคเหนือ
A8: =B8-543 -> 2025 | B8: 2568 | C8: เชียงใหม่ | D8: 1 | E8: ภงด3 | F8: 5.2473257e+08 | G8: =VLOOKUP(C8,region!$B$1:$C$78,2,FALSE) -> ภาคเหนือ | H8: ภาคเหนือ
A9: =B9-543 -> 2025 | B9: 2568 | C9: เชียงใหม่ | D9: 1 | E9: ภงด90 | F9: 3.5842526e+08 | G9: =VLOOKUP(C9,region!$B$1:$C$78,2,FALSE) -> ภาคเหนือ | H9: ภาคเหนือ
A10: =B10-543 -> 2025 | B10: 2568 | C10: เชียงใหม่ | D10: 1 | E10: ภงด91 | F10: 1.2805194e+08 | G10: =VLOOKUP(C10,region!$B$1:$C$78,2,FALSE) -> ภาคเหนือ | H10: ภาคเหนือ
A11: =B11-543 -> 2025 | B11: 2568 | C11: เชียงใหม่ | D11: 1 | E11: ภงด93 | F11: 1359717.6 | G11: =VLOOKUP(C11,region!$B$1:$C$78,2,FALSE) -> ภาคเหนือ | H11: ภาคเหนือ
A12: =B12-543 -> 2025 | B12: 2568 | C12: เชียงใหม่ | D12: 1 | E12: ภงด94 | F12: 65803215 | G12: =VLOOKUP(C12,region!$B$1:$C$78,2,FALSE) -> ภาคเหนือ | H12: ภาคเหนือ
A13: =B13-543 -> 2025 | B13: 2568 | C13: เชียงใหม่ | D13: 2 | E13: ทป3 | F13: 73988163 | G13: =VLOOKUP(C13,region!$B$1:$C$78,2,FALSE) -> ภาคเหนือ | H13: ภาคเหนือ
... A9824: =B9824-543 -> 2022 | B9824: 2565 | C9824: อุบลราชธานี | D9824: 15 | E9824: รบ1 | F9824: 785 | G9824: =VLOOKUP(C9824,region!$B$1:$C$78,2,FALSE) -> ภาคตะวันออกเฉียงเหนือ | H9824: ภาคตะวันออกเฉียงเหนือ

Sheet ประชากร
A1: year | B1: year_th | C1: ปีเดือน | D1: province_initial | E1: province | F1: region | G1: Generation | H1: Attribute | I1: ผลรวมประชากรทั้งหมด | J1: Value
A2: =B2-543 -> 2020 | B2: =_xlfn.CONCAT("25",LEFT(C2,2)) -> 2563 | C2: 6312 | D2: กรุงเทพมหานคร | E2: =VLOOKUP(D2,region!$A$1:$C$78,2,FALSE) -> นนทบุรี | F2: =VLOOKUP(E2,region!$B$1:$C$78,2,FALSE) -> กรุงเทพมหานครและปริมณฑล | G2: 0_0-15 | H2: ชาย | I2: 5588222 | J2: 385004
A3: =B3-543 -> 2020 | B3: =_xlfn.CONCAT("25",LEFT(C3,2)) -> 2563 | C3: 6312 | D3: กรุงเทพมหานคร | E3: =VLOOKUP(D3,region!$A$1:$C$78,2,FALSE) -> นนทบุรี | F3: =VLOOKUP(E3,region!$B$1:$C$78,2,FALSE) -> กรุงเทพมหานครและปริมณฑล | G3: 0_0-15 | H3: หญิง | I3: 5588222 | J3: 366807
A4: =B4-543 -> 2020 | B4: =_xlfn.CONCAT("25",LEFT(C4,2)) -> 2563 | C4: 6312 | D4: กรุงเทพมหานคร | E4: =VLOOKUP(D4,region!$A$1:$C$78,2,FALSE) -> นนทบุรี | F4: =VLOOKUP(E4,region!$B$1:$C$78,2,FALSE) -> กรุงเทพมหานครและปริมณฑล | G4: 1_15-17 | H4: ชาย | I4: 5588222 | J4: 93097
A5: =B5-543 -> 2020 | B5: =_xlfn.CONCAT("25",LEFT(C5,2)) -> 2563 | C5: 6312 | D5: กรุงเทพมหานคร | E5: =VLOOKUP(D5,region!$A$1:$C$78,2,FALSE) -> นนทบุรี | F5: =VLOOKUP(E5,region!$B$1:$C$78,2,FALSE) -> กรุงเทพมหานครและปริมณฑล | G5: 1_15-17 | H5: หญิง | I5: 5588222 | J5: 90267
A6: =B6-543 -> 2020 | B6: =_xlfn.CONCAT("25",LEFT(C6,2)) -> 2563 | C6: 6312 | D6: กรุงเทพมหานคร | E6: =VLOOKUP(D6,region!$A$1:$C$78,2,FALSE) -> นนทบุรี | F6: =VLOOKUP(E6,region!$B$1:$C$78,2,FALSE) -> กรุงเทพมหานครและปริมณฑล | G6: 10_55-59 | H6: ชาย | I6: 5588222 | J6: 183359
A7: =B7-543 -> 2020 | B7: =_xlfn.CONCAT("25",LEFT(C7,2)) -> 2563 | C7: 6312 | D7: กรุงเทพมหานคร | E7: =VLOOKUP(D7,region!$A$1:$C$78,2,FALSE) -> นนทบุรี | F7: =VLOOKUP(E7,region!$B$1:$C$78,2,FALSE) -> กรุงเทพมหานครและปริมณฑล | G7: 10_55-59 | H7: หญิง | I7: 5588222 | J7: 226991
A8: =B8-543 -> 2020 | B8: =_xlfn.CONCAT("25",LEFT(C8,2)) -> 2563 | C8: 6312 | D8: กรุงเทพมหานคร | E8: =VLOOKUP(D8,region!$A$1:$C$78,2,FALSE) -> นนทบุรี | F8: =VLOOKUP(E8,region!$B$1:$C$78,2,FALSE) -> กรุงเทพมหานครและปริมณฑล | G8: 11_morethanequal60 | H8: ชาย | I8: 5588222 | J8: 459810
A9: =B9-543 -> 2020 | B9: =_xlfn.CONCAT("25",LEFT(C9,2)) -> 2563 | C9: 6312 | D9: กรุงเทพมหานคร | E9: =VLOOKUP(D9,region!$A$1:$C$78,2,FALSE) -> นนทบุรี | F9: =VLOOKUP(E9,region!$B$1:$C$78,2,FALSE) -> กรุงเทพมหานครและปริมณฑล | G9: 11_morethanequal60 | H9: หญิง | I9: 5588222 | J9: 649102
A10: =B10-543 -> 2020 | B10: =_xlfn.CONCAT("25",LEFT(C10,2)) -> 2563 | C10: 6312 | D10: กรุงเทพมหานคร | E10: =VLOOKUP(D10,region!$A$1:$C$78,2,FALSE) -> นนทบุรี | F10: =VLOOKUP(E10,region!$B$1:$C$78,2,FALSE) -> กรุงเทพมหานครและปริมณฑล | G10: 2_18-19 | H10: ชาย | I10: 5588222 | J10: 61819
A11: =B11-543 -> 2020 | B11: =_xlfn.CONCAT("25",LEFT(C11,2)) -> 2563 | C11: 6312 | D11: กรุงเทพมหานคร | E11: =VLOOKUP(D11,region!$A$1:$C$78,2,FALSE) -> นนทบุรี | F11: =VLOOKUP(E11,region!$B$1:$C$78,2,FALSE) -> กรุงเทพมหานครและปริมณฑล | G11: 2_18-19 | H11: หญิง | I11: 5588222 | J11: 61170
A12: =B12-543 -> 2020 | B12: =_xlfn.CONCAT("25",LEFT(C12,2)) -> 2563 | C12: 6312 | D12: กรุงเทพมหานคร | E12: =VLOOKUP(D12,region!$A$1:$C$78,2,FALSE) -> นนทบุรี | F12: =VLOOKUP(E12,region!$B$1:$C$78,2,FALSE) -> กรุงเทพมหานครและปริมณฑล | G12: 3_20-24 | H12: ชาย | I12: 5588222 | J12: 189345
A13: =B13-543 -> 2020 | B13: =_xlfn.CONCAT("25",LEFT(C13,2)) -> 2563 | C13: 6312 | D13: กรุงเทพมหานคร | E13: =VLOOKUP(D13,region!$A$1:$C$78,2,FALSE) -> นนทบุรี | F13: =VLOOKUP(E13,region!$B$1:$C$78,2,FALSE) -> กรุงเทพมหานครและปริมณฑล | G13: 3_20-24 | H13: หญิง | I13: 5588222 | J13: 176355
... A11089: =B11089-543 -> 2021 | B11089: =_xlfn.CONCAT("25",LEFT(C11089,2)) -> 2564 | C11089: 6412 | D11089: จังหวัดยะลา | E11089: =VLOOKUP(D11089,region!$A$1:$C$78,2,FALSE) -> ศรีสะเกษ | F11089: =VLOOKUP(E11089,region!$B$1:$C$78,2,FALSE) -> ภาคตะวันออกเฉียงเหนือ | G11089: 9_50-54 | H11089: หญิง | I11089: 542314 | J11089: 15619

Sheet แรงงาน
A1: year | B1: year_th | C1: quarter | D1: province | E1: region | F1: labor_force | G1: labor_force_status | H1: value | I1: unit | J1: attribute | K1: source
A2: =B2-543 -> 2021 | B2: 2564 | C2: ไตรมาสที่ 1 | D2: กรุงเทพมหานคร | E2: =VLOOKUP(D2,region!$B$1:$C$78,2,FALSE) -> กรุงเทพมหานครและปริมณฑล | F2: กำลังแรงงานรวม | G2: รวม | H2: 5571268 | I2: คน | K2: สำนักงานสถิติแห่งชาติ
A3: =B3-543 -> 2021 | B3: 2564 | C3: ไตรมาสที่ 1 | D3: กรุงเทพมหานคร | E3: =VLOOKUP(D3,region!$B$1:$C$78,2,FALSE) -> กรุงเทพมหานครและปริมณฑล | F3: กำลังแรงงานรวม | G3: กำลังแรงงานปัจจุบัน_รวม | H3: 5570332 | I3: คน | K3: สำนักงานสถิติแห่งชาติ
A4: =B4-543 -> 2021 | B4: 2564 | C4: ไตรมาสที่ 1 | D4: กรุงเทพมหานคร | E4: =VLOOKUP(D4,region!$B$1:$C$78,2,FALSE) -> กรุงเทพมหานครและปริมณฑล | F4: กำลังแรงงานรวม | G4: กำลังแรงงานปัจจุบัน_ผู้มีงานทำ | H4: 5445329 | I4: คน | K4: สำนักงานสถิติแห่งชาติ
A5: =B5-543 -> 2021 | B5: 2564 | C5: ไตรมาสที่ 1 | D5: กรุงเทพมหานคร | E5: =VLOOKUP(D5,region!$B$1:$C$78,2,FALSE) -> กรุงเทพมหานครและปริมณฑล | F5: กำลังแรงงานรวม | G5: กำลังแรงงานปัจจุบัน_ผู้ว่างงาน | H5: 125004 | I5: คน | K5: สำนักงานสถิติแห่งชาติ
A6: =B6-543 -> 2021 | B6: 2564 | C6: ไตรมาสที่ 1 | D6: กรุงเทพมหานคร | E6: =VLOOKUP(D6,region!$B$1:$C$78,2,FALSE) -> กรุงเทพมหานครและปริมณฑล | F6: กำลังแรงงานรวม | G6: กำลังแรงงานที่รอฤดูกาล | H6: 935 | I6: คน | K6: สำนักงานสถิติแห่งชาติ
A7: =B7-543 -> 2021 | B7: 2564 | C7: ไตรมาสที่ 1 | D7: กรุงเทพมหานคร | E7: =VLOOKUP(D7,region!$B$1:$C$78,2,FALSE) -> กรุงเทพมหานครและปริมณฑล | F7: ผู้อยู่นอกกำลังแรงงาน | G7: รวม | H7: 2086332 | I7: คน | K7: สำนักงานสถิติแห่งชาติ
A8: =B8-543 -> 2021 | B8: 2564 | C8: ไตรมาสที่ 1 | D8: กรุงเทพมหานคร | E8: =VLOOKUP(D8,region!$B$1:$C$78,2,FALSE) -> กรุงเทพมหานครและปริมณฑล | F8: ผู้อยู่นอกกำลังแรงงาน | G8: ทำงานบ้าน | H8: 538276 | I8: คน | K8: สำนักงานสถิติแห่งชาติ
A9: =B9-543 -> 2021 | B9: 2564 | C9: ไตรมาสที่ 1 | D9: กรุงเทพมหานคร | E9: =VLOOKUP(D9,region!$B$1:$C$78,2,FALSE) -> กรุงเทพมหานครและปริมณฑล | F9: ผู้อยู่นอกกำลังแรงงาน | G9: เรียนหนังสือ | H9: 488201 | I9: คน | K9: สำนักงานสถิติแห่งชาติ
A10: =B10-543 -> 2021 | B10: 2564 | C10: ไตรมาสที่ 1 | D10: กรุงเทพมหานคร | E10: =VLOOKUP(D10,region!$B$1:$C$78,2,FALSE) -> กรุงเทพมหานครและปริมณฑล | F10: ผู้อยู่นอกกำลังแรงงาน | G10: อื่น ๆ | H10: 1059855 | I10: คน | K10: สำนักงานสถิติแห่งชาติ
A11: =B11-543 -> 2021 | B11: 2564 | C11: ไตรมาสที่ 2 | D11: กรุงเทพมหานคร | E11: =VLOOKUP(D11,region!$B$1:$C$78,2,FALSE) -> กรุงเทพมหานครและปริมณฑล | F11: กำลังแรงงานรวม | G11: รวม | H11: 5513652 | I11: คน | K11: สำนักงานสถิติแห่งชาติ
A12: =B12-543 -> 2021 | B12: 2564 | C12: ไตรมาสที่ 2 | D12: กรุงเทพมหานคร | E12: =VLOOKUP(D12,region!$B$1:$C$78,2,FALSE) -> กรุงเทพมหานครและปริมณฑล | F12: กำลังแรงงานรวม | G12: กำลังแรงงานปัจจุบัน_รวม | H12: 5511062 | I12: คน | K12: สำนักงานสถิติแห่งชาติ
A13: =B13-543 -> 2021 | B13: 2564 | C13: ไตรมาสที่ 2 | D13: กรุงเทพมหานคร | E13: =VLOOKUP(D13,region!$B$1:$C$78,2,FALSE) -> กรุงเทพมหานครและปริมณฑล | F13: กำลังแรงงานรวม | G13: กำลังแรงงานปัจจุบัน_ผู้มีงานทำ | H13: 5374236 | I13: คน | K13: สำนักงานสถิติแห่งชาติ
... A59: =B59-543 -> 2022 | B59: 2565 | C59: ไตรมาสที่ 3 | D59: กรุงเทพมหานคร | E59: =VLOOKUP(D59,region!$B$1:$C$78,2,FALSE) -> กรุงเทพมหานครและปริมณฑล | F59: กำลังแรงงานรวม | G59: กำลังแรงงานปัจจุบัน_ผู้ว่างงาน | H59: 65051 | I59: คน | K59: สำนักงานสถิติแห่งชาติ
A60: =B60-543 -> 2022 | B60: 2565 | C60: ไตรมาสที่ 3 | D60: กรุงเทพมหานคร | E60: =VLOOKUP(D60,region!$B$1:$C$78,2,FALSE) -> กรุงเทพมหานครและปริมณฑล | F60: กำลังแรงงานรวม | G60: กำลังแรงงานที่รอฤดูกาล | H60: 0 | I60: คน | J60: ศูนย์ยกกำลังดับเบิลยู หมายถึง ข้อมูลจากการสำรวจตัวอย่างมีค่าเป็น 0 | K60: สำนักงานสถิติแห่งชาติ
A61: =B61-543 -> 2022 | B61: 2565 | C61: ไตรมาสที่ 3 | D61: กรุงเทพมหานคร | E61: =VLOOKUP(D61,region!$B$1:$C$78,2,FALSE) -> กรุงเทพมหานครและปริมณฑล | F61: ผู้อยู่นอกกำลังแรงงาน | G61: รวม | H61: 2159185 | I61: คน | K61: สำนักงานสถิติแห่งชาติ
A62: =B62-543 -> 2022 | B62: 2565 | C62: ไตรมาสที่ 3 | D62: กรุงเทพมหานคร | E62: =VLOOKUP(D62,region!$B$1:$C$78,2,FALSE) -> กรุงเทพมหานครและปริมณฑล | F62: ผู้อยู่นอกกำลังแรงงาน | G62: ทำงานบ้าน | H62: 581516 | I62: คน | K62: สำนักงานสถิติแห่งชาติ
A63: =B63-543 -> 2022 | B63: 2565 | C63: ไตรมาสที่ 3 | D63: กรุงเทพมหานคร | E63: =VLOOKUP(D63,region!$B$1:$C$78,2,FALSE) -> กรุงเทพมหานครและปริมณฑล | F63: ผู้อยู่นอกกำลังแรงงาน | G63: เรียนหนังสือ | H63: 450011 | I63: คน | K63: สำนักงานสถิติแห่งชาติ
A64: =B64-543 -> 2022 | B64: 2565 | C64: ไตรมาสที่ 3 | D64: กรุงเทพมหานคร | E64: =VLOOKUP(D64,region!$B$1:$C$78,2,FALSE) -> กรุงเทพมหานครและปริมณฑล | F64: ผู้อยู่นอกกำลังแรงงาน | G64: อื่น ๆ | H64: 1127658 | I64: คน | K64: สำนักงานสถิติแห่งชาติ
A65: =B65-543 -> 2022 | B65: 2565 | C65: ไตรมาสที่ 4 | D65: กรุงเทพมหานคร | E65: =VLOOKUP(D65,region!$B$1:$C$78,2,FALSE) -> กรุงเทพมหานครและปริมณฑล | F65: กำลังแรงงานรวม | G65: รวม | H65: 5762451 | I65: คน | K65: สำนักงานสถิติแห่งชาติ
A66: =B66-543 -> 2022 | B66: 2565 | C66: ไตรมาสที่ 4 | D66: กรุงเทพมหานคร | E66: =VLOOKUP(D66,region!$B$1:$C$78,2,FALSE) -> กรุงเทพมหานครและปริมณฑล | F66: กำลังแรงงานรวม | G66: กำลังแรงงานปัจจุบัน_รวม | H66: 5762451 | I66: คน | K66: สำนักงานสถิติแห่งชาติ
A67: =B67-543 -> 2022 | B67: 2565 | C67: ไตรมาสที่ 4 | D67: กรุงเทพมหานคร | E67: =VLOOKUP(D67,region!$B$1:$C$78,2,FALSE) -> กรุงเทพมหานครและปริมณฑล | F67: กำลังแรงงานรวม | G67: กำลังแรงงานปัจจุบัน_ผู้มีงานทำ | H67: 5692759 | I67: คน | K67: สำนักงานสถิติแห่งชาติ
A68: =B68-543 -> 2022 | B68: 2565 | C68: ไตรมาสที่ 4 | D68: กรุงเทพมหานคร | E68: =VLOOKUP(D68,region!$B$1:$C$78,2,FALSE) -> กรุงเทพมหานครและปริมณฑล | F68: กำลังแรงงานรวม | G68: กำลังแรงงานปัจจุบัน_ผู้ว่างงาน | H68: 69692 | I68: คน | K68: สำนักงานสถิติแห่งชาติ
A69: =B69-543 -> 2022 | B69: 2565 | C69: ไตรมาสที่ 4 | D69: กรุงเทพมหานคร | E69: =VLOOKUP(D69,region!$B$1:$C$78,2,FALSE) -> กรุงเทพมหานครและปริมณฑล | F69: กำลังแรงงานรวม | G69: กำลังแรงงานที่รอฤดูกาล | H69: 0 | I69: คน | J69: ศูนย์ยกกำลังดับเบิลยู หมายถึง ข้อมูลจากการสำรวจตัวอย่างมีค่าเป็น 0 | K69: สำนักงานสถิติแห่งชาติ
A70: =B70-543 -> 2022 | B70: 2565 | C70: ไตรมาสที่ 4 | D70: กรุงเทพมหานคร | E70: =VLOOKUP(D70,region!$B$1:$C$78,2,FALSE) -> กรุงเทพมหานครและปริมณฑล | F70: ผู้อยู่นอกกำลังแรงงาน | G70: รวม | H70: 2100939 | I70: คน | K70: สำนักงานสถิติแห่งชาติ
A71: =B71-543 -> 2022 | B71: 2565 | C71: ไตรมาสที่ 4 | D71: กรุงเทพมหานคร | E71: =VLOOKUP(D71,region!$B$1:$C$78,2,FALSE) -> กรุงเทพมหานครและปริมณฑล | F71: ผู้อยู่นอกกำลังแรงงาน | G71: ทำงานบ้าน | H71: 550437 | I71: คน | K71: สำนักงานสถิติแห่งชาติ
A72: =B72-543 -> 2022 | B72: 2565 | C72: ไตรมาสที่ 4 | D72: กรุงเทพมหานคร | E72: =VLOOKUP(D72,region!$B$1:$C$78,2,FALSE) -> กรุงเทพมหานครและปริมณฑล | F72: ผู้อยู่นอกกำลังแรงงาน | G72: เรียนหนังสือ | H72: 479829 | I72: คน | K72: สำนักงานสถิติแห่งชาติ
A73: =B73-543 -> 2022 | B73: 2565 | C73: ไตรมาสที่ 4 | D73: กรุงเทพมหานคร | E73: =VLOOKUP(D73,region!$B$1:$C$78,2,FALSE) -> กรุงเทพมหานครและปริมณฑล | F73: ผู้อยู่นอกกำลังแรงงาน | G73: อื่น ๆ | H73: 1070672 | I73: คน | K73: สำนักงานสถิติแห่งชาติ
A74: =B74-543 -> 2023 | B74: 2566 | C74: ไตรมาสที่ 1 | D74: กรุงเทพมหานคร | E74: =VLOOKUP(D74,region!$B$1:$C$78,2,FALSE) -> กรุงเทพมหานครและปริมณฑล | F74: กำลังแรงงานรวม | G74: รวม | H74: 5819799 | I74: คน | K74: สำนักงานสถิติแห่งชาติ
A75: =B75-543 -> 2023 | B75: 2566 | C75: ไตรมาสที่ 1 | D75: กรุงเทพมหานคร | E75: =VLOOKUP(D75,region!$B$1:$C$78,2,FALSE) -> กรุงเทพมหานครและปริมณฑล | F75: กำลังแรงงานรวม | G75: กำลังแรงงานปัจจุบัน_รวม | H75: 5818136 | I75: คน | K75: สำนักงานสถิติแห่งชาติ
A76: =B76-543 -> 2023 | B76: 2566 | C76: ไตรมาสที่ 1 | D76: กรุงเทพมหานคร | E76: =VLOOKUP(D76,region!$B$1:$C$78,2,FALSE) -> กรุงเทพมหานครและปริมณฑล | F76: กำลังแรงงานรวม | G76: กำลังแรงงานปัจจุบัน_ผู้มีงานทำ | H76: 5755751 | I76: คน | K76: สำนักงานสถิติแห่งชาติ
A77: =B77-543 -> 2023 | B77: 2566 | C77: ไตรมาสที่ 1 | D77: กรุงเทพมหานคร | E77: =VLOOKUP(D77,region!$B$1:$C$78,2,FALSE) -> กรุงเทพมหานครและปริมณฑล | F77: กำลังแรงงานรวม | G77: กำลังแรงงานปัจจุบัน_ผู้ว่างงาน | H77: 62386 | I77: คน | K77: สำนักงานสถิติแห่งชาติ
A78: =B78-543 -> 2023 | B78: 2566 | C78: ไตรมาสที่ 1 | D78: กรุงเทพมหานคร | E78: =VLOOKUP(D78,region!$B$1:$C$78,2,FALSE) -> กรุงเทพมหานครและปริมณฑล | F78: กำลังแรงงานรวม | G78: กำลังแรงงานที่รอฤดูกาล | H78: 1663 | I78: คน | K78: สำนักงานสถิติแห่งชาติ
A79: =B79-543 -> 2023 | B79: 2566 | C79: ไตรมาสที่ 1 | D79: กรุงเทพมหานคร | E79: =VLOOKUP(D79,region!$B$1:$C$78,2,FALSE) -> กรุงเทพมหานครและปริมณฑล | F79: ผู้อยู่นอกกำลังแรงงาน | G79: รวม | H79: 2048391 | I79: คน | K79: สำนักงานสถิติแห่งชาติ
A80: =B80-543 -> 2023 | B80: 2566 | C80: ไตรมาสที่ 1 | D80: กรุงเทพมหานคร | E80: =VLOOKUP(D80,region!$B$1:$C$78,2,FALSE) -> กรุงเทพมหานครและปริมณฑล | F80: ผู้อยู่นอกกำลังแรงงาน | G80: ทำงานบ้าน | H80: 549838 | I80: คน | K80: สำนักงานสถิติแห่งชาติ
A81: =B81-543 -> 2023 | B81: 2566 | C81: ไตรมาสที่ 1 | D81: กรุงเทพมหานคร | E81: =VLOOKUP(D81,region!$B$1:$C$78,2,FALSE) -> กรุงเทพมหานครและปริมณฑล | F81: ผู้อยู่นอกกำลังแรงงาน | G81: เรียนหนังสือ | H81: 497313 | I81: คน | K81: สำนักงานสถิติแห่งชาติ
... A131: =B131-543 -> 2024 | B131: 2567 | C131: ไตรมาสที่ 3 | D131: กรุงเทพมหานคร | E131: =VLOOKUP(D131,region!$B$1:$C$78,2,FALSE) -> กรุงเทพมหานครและปริมณฑล | F131: กำลังแรงงานรวม | G131: กำลังแรงงานปัจจุบัน_ผู้ว่างงาน | H131: 67460 | I131: คน | K131: สำนักงานสถิติแห่งชาติ
A132: =B132-543 -> 2024 | B132: 2567 | C132: ไตรมาสที่ 3 | D132: กรุงเทพมหานคร | E132: =VLOOKUP(D132,region!$B$1:$C$78,2,FALSE) -> กรุงเทพมหานครและปริมณฑล | F132: กำลังแรงงานรวม | G132: กำลังแรงงานที่รอฤดูกาล | H132: 0 | I132: คน | J132: ศูนย์ยกกำลังดับเบิลยู หมายถึง ข้อมูลจากการสำรวจตัวอย่างมีค่าเป็น 0 | K132: สำนักงานสถิติแห่งชาติ
A133: =B133-543 -> 2024 | B133: 2567 | C133: ไตรมาสที่ 3 | D133: กรุงเทพมหานคร | E133: =VLOOKUP(D133,region!$B$1:$C$78,2,FALSE) -> กรุงเทพมหานครและปริมณฑล | F133: ผู้อยู่นอกกำลังแรงงาน | G133: รวม | H133: 2136038 | I133: คน | K133: สำนักงานสถิติแห่งชาติ
A134: =B134-543 -> 2024 | B134: 2567 | C134: ไตรมาสที่ 3 | D134: กรุงเทพมหานคร | E134: =VLOOKUP(D134,region!$B$1:$C$78,2,FALSE) -> กรุงเทพมหานครและปริมณฑล | F134: ผู้อยู่นอกกำลังแรงงาน | G134: ทำงานบ้าน | H134: 522857 | I134: คน | K134: สำนักงานสถิติแห่งชาติ
...

Sheet region
A1: จังหวัด | B1: province | C1: region
A2: จังหวัดกระบี่ | B2: กรุงเทพมหานคร | C2: กรุงเทพมหานครและปริมณฑล
A3: กรุงเทพมหานคร | B3: นนทบุรี | C3: กรุงเทพมหานครและปริมณฑล
A4: จังหวัดกาญจนบุรี | B4: ปทุมธานี | C4: กรุงเทพมหานครและปริมณฑล
A5: จังหวัดกาฬสินธุ์ | B5: สมุทรปราการ | C5: กรุงเทพมหานครและปริมณฑล
A6: จังหวัดกำแพงเพชร | B6: สมุทรสาคร | C6: กรุงเทพมหานครและปริมณฑล
A7: จังหวัดขอนแก่น | B7: นครปฐม | C7: กรุงเทพมหานครและปริมณฑล
A8: จังหวัดจันทบุรี | B8: กำแพงเพชร | C8: ภาคกลาง
A9: จังหวัดฉะเชิงเทรา | B9: ชัยนาท | C9: ภาคกลาง
A10: จังหวัดชลบุรี | B10: นครนายก | C10: ภาคกลาง
A11: จังหวัดชัยนาท | B11: นครสวรรค์ | C11: ภาคกลาง
A12: จังหวัดชัยภูมิ | B12: พระนครศรีอยุธยา | C12: ภาคกลาง
... A78: จังหวัดอุบลราชธานี | B78: ยะลา | C78: ภาคใต้
